2025-10-11 19:36:56 | ERROR | api_exceptions | Unexpected exception in API | trace_id=39a223ed-e0fe-40d8-9020-e3b11ea35756 | path=/api/messages | method=POST | exception_type=RuntimeError | exception_message=Unexpected error
  + Exception Group Traceback (most recent call last):
  |   File "C:\Projects\bot_framework\venv\Lib\site-packages\starlette\_utils.py", line 76, in collapse_excgroups
  |     yield
  |   File "C:\Projects\bot_framework\venv\Lib\site-packages\starlette\middleware\base.py", line 177, in __call__
  |     async with anyio.create_task_group() as task_group:
  |                ~~~~~~~~~~~~~~~~~~~~~~~^^
  |   File "C:\Projects\bot_framework\venv\Lib\site-packages\anyio\_backends\_asyncio.py", line 772, in __aexit__
  |     raise BaseExceptionGroup(
  |         "unhandled errors in a TaskGroup", self._exceptions
  |     ) from None
  | ExceptionGroup: unhandled errors in a TaskGroup (1 sub-exception)
  +-+---------------- 1 ----------------
    | Traceback (most recent call last):
    |   File "C:\Projects\bot_framework\venv\Lib\site-packages\starlette\middleware\errors.py", line 165, in __call__
    |     await self.app(scope, receive, _send)
    |   File "C:\Projects\bot_framework\venv\Lib\site-packages\starlette\middleware\base.py", line 176, in __call__
    |     with recv_stream, send_stream, collapse_excgroups():
    |                                    ~~~~~~~~~~~~~~~~~~^^
    |   File "C:\Python313\Lib\contextlib.py", line 162, in __exit__
    |     self.gen.throw(value)
    |     ~~~~~~~~~~~~~~^^^^^^^
    |   File "C:\Projects\bot_framework\venv\Lib\site-packages\starlette\_utils.py", line 82, in collapse_excgroups
    |     raise exc
    |   File "C:\Projects\bot_framework\venv\Lib\site-packages\starlette\middleware\base.py", line 178, in __call__
    |     response = await self.dispatch_func(request, call_next)
    |                ^^^^^^^^^^^^^^^^^^^^^^^^^^^^^^^^^^^^^^^^^^^^
    |   File "C:\Projects\bot_framework\api\middleware.py", line 58, in request_logging_middleware
    |     response = await call_next(request)
    |                ^^^^^^^^^^^^^^^^^^^^^^^^
    |   File "C:\Projects\bot_framework\venv\Lib\site-packages\starlette\middleware\base.py", line 156, in call_next
    |     raise app_exc
    |   File "C:\Projects\bot_framework\venv\Lib\site-packages\starlette\middleware\base.py", line 141, in coro
    |     await self.app(scope, receive_or_disconnect, send_no_error)
    |   File "C:\Projects\bot_framework\venv\Lib\site-packages\starlette\middleware\cors.py", line 85, in __call__
    |     await self.app(scope, receive, send)
    |   File "C:\Projects\bot_framework\venv\Lib\site-packages\starlette\middleware\exceptions.py", line 62, in __call__
    |     await wrap_app_handling_exceptions(self.app, conn)(scope, receive, send)
    |   File "C:\Projects\bot_framework\venv\Lib\site-packages\starlette\_exception_handler.py", line 53, in wrapped_app
    |     raise exc
    |   File "C:\Projects\bot_framework\venv\Lib\site-packages\starlette\_exception_handler.py", line 42, in wrapped_app
    |     await app(scope, receive, sender)
    |   File "C:\Projects\bot_framework\venv\Lib\site-packages\starlette\routing.py", line 714, in __call__
    |     await self.middleware_stack(scope, receive, send)
    |   File "C:\Projects\bot_framework\venv\Lib\site-packages\starlette\routing.py", line 734, in app
    |     await route.handle(scope, receive, send)
    |   File "C:\Projects\bot_framework\venv\Lib\site-packages\starlette\routing.py", line 288, in handle
    |     await self.app(scope, receive, send)
    |   File "C:\Projects\bot_framework\venv\Lib\site-packages\starlette\routing.py", line 76, in app
    |     await wrap_app_handling_exceptions(app, request)(scope, receive, send)
    |   File "C:\Projects\bot_framework\venv\Lib\site-packages\starlette\_exception_handler.py", line 53, in wrapped_app
    |     raise exc
    |   File "C:\Projects\bot_framework\venv\Lib\site-packages\starlette\_exception_handler.py", line 42, in wrapped_app
    |     await app(scope, receive, sender)
    |   File "C:\Projects\bot_framework\venv\Lib\site-packages\starlette\routing.py", line 73, in app
    |     response = await f(request)
    |                ^^^^^^^^^^^^^^^^
    |   File "C:\Projects\bot_framework\venv\Lib\site-packages\fastapi\routing.py", line 301, in app
    |     raw_response = await run_endpoint_function(
    |                    ^^^^^^^^^^^^^^^^^^^^^^^^^^^^
    |     ...<3 lines>...
    |     )
    |     ^
    |   File "C:\Projects\bot_framework\venv\Lib\site-packages\fastapi\routing.py", line 214, in run_endpoint_function
    |     return await run_in_threadpool(dependant.call, **values)
    |            ^^^^^^^^^^^^^^^^^^^^^^^^^^^^^^^^^^^^^^^^^^^^^^^^^
    |   File "C:\Projects\bot_framework\venv\Lib\site-packages\starlette\concurrency.py", line 37, in run_in_threadpool
    |     return await anyio.to_thread.run_sync(func)
    |            ^^^^^^^^^^^^^^^^^^^^^^^^^^^^^^^^^^^^
    |   File "C:\Projects\bot_framework\venv\Lib\site-packages\anyio\to_thread.py", line 56, in run_sync
    |     return await get_async_backend().run_sync_in_worker_thread(
    |            ^^^^^^^^^^^^^^^^^^^^^^^^^^^^^^^^^^^^^^^^^^^^^^^^^^^^
    |         func, args, abandon_on_cancel=abandon_on_cancel, limiter=limiter
    |         ^^^^^^^^^^^^^^^^^^^^^^^^^^^^^^^^^^^^^^^^^^^^^^^^^^^^^^^^^^^^^^^^
    |     )
    |     ^
    |   File "C:\Projects\bot_framework\venv\Lib\site-packages\anyio\_backends\_asyncio.py", line 2470, in run_sync_in_worker_thread
    |     return await future
    |            ^^^^^^^^^^^^
    |   File "C:\Projects\bot_framework\venv\Lib\site-packages\anyio\_backends\_asyncio.py", line 967, in run
    |     result = context.run(func, *args)
    |   File "C:\Projects\bot_framework\api\routes\messages.py", line 20, in handle_api_message
    |     result = process_message(
    |         db=db,
    |     ...<5 lines>...
    |         channel="api"
    |     )
    |   File "C:\Python313\Lib\unittest\mock.py", line 1169, in __call__
    |     return self._mock_call(*args, **kwargs)
    |            ~~~~~~~~~~~~~~~^^^^^^^^^^^^^^^^^
    |   File "C:\Python313\Lib\unittest\mock.py", line 1173, in _mock_call
    |     return self._execute_mock_call(*args, **kwargs)
    |            ~~~~~~~~~~~~~~~~~~~~~~~^^^^^^^^^^^^^^^^^
    |   File "C:\Python313\Lib\unittest\mock.py", line 1228, in _execute_mock_call
    |     raise effect
    | RuntimeError: Unexpected error
    +------------------------------------

During handling of the above exception, another exception occurred:

Traceback (most recent call last):
  File "C:\Projects\bot_framework\venv\Lib\site-packages\starlette\middleware\errors.py", line 165, in __call__
    await self.app(scope, receive, _send)
  File "C:\Projects\bot_framework\venv\Lib\site-packages\starlette\middleware\base.py", line 176, in __call__
    with recv_stream, send_stream, collapse_excgroups():
                                   ~~~~~~~~~~~~~~~~~~^^
  File "C:\Python313\Lib\contextlib.py", line 162, in __exit__
    self.gen.throw(value)
    ~~~~~~~~~~~~~~^^^^^^^
  File "C:\Projects\bot_framework\venv\Lib\site-packages\starlette\_utils.py", line 82, in collapse_excgroups
    raise exc
  File "C:\Projects\bot_framework\venv\Lib\site-packages\starlette\middleware\base.py", line 178, in __call__
    response = await self.dispatch_func(request, call_next)
               ^^^^^^^^^^^^^^^^^^^^^^^^^^^^^^^^^^^^^^^^^^^^
  File "C:\Projects\bot_framework\api\middleware.py", line 58, in request_logging_middleware
    response = await call_next(request)
               ^^^^^^^^^^^^^^^^^^^^^^^^
  File "C:\Projects\bot_framework\venv\Lib\site-packages\starlette\middleware\base.py", line 156, in call_next
    raise app_exc
  File "C:\Projects\bot_framework\venv\Lib\site-packages\starlette\middleware\base.py", line 141, in coro
    await self.app(scope, receive_or_disconnect, send_no_error)
  File "C:\Projects\bot_framework\venv\Lib\site-packages\starlette\middleware\cors.py", line 85, in __call__
    await self.app(scope, receive, send)
  File "C:\Projects\bot_framework\venv\Lib\site-packages\starlette\middleware\exceptions.py", line 62, in __call__
    await wrap_app_handling_exceptions(self.app, conn)(scope, receive, send)
  File "C:\Projects\bot_framework\venv\Lib\site-packages\starlette\_exception_handler.py", line 53, in wrapped_app
    raise exc
  File "C:\Projects\bot_framework\venv\Lib\site-packages\starlette\_exception_handler.py", line 42, in wrapped_app
    await app(scope, receive, sender)
  File "C:\Projects\bot_framework\venv\Lib\site-packages\starlette\routing.py", line 714, in __call__
    await self.middleware_stack(scope, receive, send)
  File "C:\Projects\bot_framework\venv\Lib\site-packages\starlette\routing.py", line 734, in app
    await route.handle(scope, receive, send)
  File "C:\Projects\bot_framework\venv\Lib\site-packages\starlette\routing.py", line 288, in handle
    await self.app(scope, receive, send)
  File "C:\Projects\bot_framework\venv\Lib\site-packages\starlette\routing.py", line 76, in app
    await wrap_app_handling_exceptions(app, request)(scope, receive, send)
  File "C:\Projects\bot_framework\venv\Lib\site-packages\starlette\_exception_handler.py", line 53, in wrapped_app
    raise exc
  File "C:\Projects\bot_framework\venv\Lib\site-packages\starlette\_exception_handler.py", line 42, in wrapped_app
    await app(scope, receive, sender)
  File "C:\Projects\bot_framework\venv\Lib\site-packages\starlette\routing.py", line 73, in app
    response = await f(request)
               ^^^^^^^^^^^^^^^^
  File "C:\Projects\bot_framework\venv\Lib\site-packages\fastapi\routing.py", line 301, in app
    raw_response = await run_endpoint_function(
                   ^^^^^^^^^^^^^^^^^^^^^^^^^^^^
    ...<3 lines>...
    )
    ^
  File "C:\Projects\bot_framework\venv\Lib\site-packages\fastapi\routing.py", line 214, in run_endpoint_function
    return await run_in_threadpool(dependant.call, **values)
           ^^^^^^^^^^^^^^^^^^^^^^^^^^^^^^^^^^^^^^^^^^^^^^^^^
  File "C:\Projects\bot_framework\venv\Lib\site-packages\starlette\concurrency.py", line 37, in run_in_threadpool
    return await anyio.to_thread.run_sync(func)
           ^^^^^^^^^^^^^^^^^^^^^^^^^^^^^^^^^^^^
  File "C:\Projects\bot_framework\venv\Lib\site-packages\anyio\to_thread.py", line 56, in run_sync
    return await get_async_backend().run_sync_in_worker_thread(
           ^^^^^^^^^^^^^^^^^^^^^^^^^^^^^^^^^^^^^^^^^^^^^^^^^^^^
        func, args, abandon_on_cancel=abandon_on_cancel, limiter=limiter
        ^^^^^^^^^^^^^^^^^^^^^^^^^^^^^^^^^^^^^^^^^^^^^^^^^^^^^^^^^^^^^^^^
    )
    ^
  File "C:\Projects\bot_framework\venv\Lib\site-packages\anyio\_backends\_asyncio.py", line 2470, in run_sync_in_worker_thread
    return await future
           ^^^^^^^^^^^^
  File "C:\Projects\bot_framework\venv\Lib\site-packages\anyio\_backends\_asyncio.py", line 967, in run
    result = context.run(func, *args)
  File "C:\Projects\bot_framework\api\routes\messages.py", line 20, in handle_api_message
    result = process_message(
        db=db,
    ...<5 lines>...
        channel="api"
    )
  File "C:\Python313\Lib\unittest\mock.py", line 1169, in __call__
    return self._mock_call(*args, **kwargs)
           ~~~~~~~~~~~~~~~^^^^^^^^^^^^^^^^^
  File "C:\Python313\Lib\unittest\mock.py", line 1173, in _mock_call
    return self._execute_mock_call(*args, **kwargs)
           ~~~~~~~~~~~~~~~~~~~~~~~^^^^^^^^^^^^^^^^^
  File "C:\Python313\Lib\unittest\mock.py", line 1228, in _execute_mock_call
    raise effect
RuntimeError: Unexpected error
